Traceback (most recent call last):
  File "c:\users\lenovo\appdata\local\programs\python\python39\lib\site-packages\jupyter_core\utils\__init__.py", line 154, in wrapped
    asyncio.get_running_loop()
RuntimeError: no running event loop

During handling of the above exception, another exception occurred:

Traceback (most recent call last):
  File "c:\users\lenovo\appdata\local\programs\python\python39\lib\site-packages\jupyter_cache\executors\utils.py", line 58, in single_nb_execution
    executenb(
  File "c:\users\lenovo\appdata\local\programs\python\python39\lib\site-packages\nbclient\client.py", line 1319, in execute
    return NotebookClient(nb=nb, resources=resources, km=km, **kwargs).execute()
  File "c:\users\lenovo\appdata\local\programs\python\python39\lib\site-packages\jupyter_core\utils\__init__.py", line 158, in wrapped
    return loop.run_until_complete(inner)
  File "c:\users\lenovo\appdata\local\programs\python\python39\lib\asyncio\base_events.py", line 642, in run_until_complete
    return future.result()
  File "c:\users\lenovo\appdata\local\programs\python\python39\lib\site-packages\nbclient\client.py", line 709, in async_execute
    await self.async_execute_cell(
  File "c:\users\lenovo\appdata\local\programs\python\python39\lib\site-packages\nbclient\client.py", line 1062, in async_execute_cell
    await self._check_raise_for_error(cell, cell_index, exec_reply)
  File "c:\users\lenovo\appdata\local\programs\python\python39\lib\site-packages\nbclient\client.py", line 918, in _check_raise_for_error
    raise CellExecutionError.from_cell_and_msg(cell, exec_reply_content)
nbclient.exceptions.CellExecutionError: An error occurred while executing the following cell:
------------------
## SETUP

# Import library dasar
import pandas as pd
import numpy as np
import time

# Import untuk LDA & Koherensi
import gensim
from gensim.corpora import Dictionary
from gensim.models import LdaMulticore, CoherenceModel, HdpModel

# Import untuk Klasifikasi & Evaluasi
from sklearn.model_selection import train_test_split
from sklearn.svm import SVC
from sklearn.metrics import classification_report, accuracy_score

# Import untuk Visualisasi
import matplotlib.pyplot as plt
from sklearn.preprocessing import StandardScaler
from matplotlib import cm
from matplotlib.lines import Line2D
import umap

print("Semua library berhasil diimpor.")


------------------


[1;31m---------------------------------------------------------------------------[0m
[1;31mModuleNotFoundError[0m                       Traceback (most recent call last)
Cell [1;32mIn[2], line 23[0m
[0;32m     21[0m [38;5;28;01mfrom[39;00m[38;5;250m [39m[38;5;21;01mmatplotlib[39;00m[38;5;250m [39m[38;5;28;01mimport[39;00m cm
[0;32m     22[0m [38;5;28;01mfrom[39;00m[38;5;250m [39m[38;5;21;01mmatplotlib[39;00m[38;5;21;01m.[39;00m[38;5;21;01mlines[39;00m[38;5;250m [39m[38;5;28;01mimport[39;00m Line2D
[1;32m---> 23[0m [38;5;28;01mimport[39;00m[38;5;250m [39m[38;5;21;01mumap[39;00m
[0;32m     25[0m [38;5;28mprint[39m([38;5;124m"[39m[38;5;124mSemua library berhasil diimpor.[39m[38;5;124m"[39m)

[1;31mModuleNotFoundError[0m: No module named 'umap'

